>>> 'Pkg.add("GeographicLibPy")' log
INFO: Cloning cache of GeographicLibPy from git://github.com/kshramt/GeographicLibPy.jl.git
INFO: Installing BinDeps v0.4.7
INFO: Installing Conda v0.5.3
INFO: Installing GeographicLibPy v0.0.3
INFO: Installing MacroTools v0.3.7
INFO: Installing PyCall v1.11.1
INFO: Installing SHA v0.3.3
INFO: Installing URIParser v0.1.8
INFO: Building Conda
INFO: Building PyCall
INFO: Using the Python distribution in the Conda package by default.
To use a different Python version, set ENV["PYTHON"]="pythoncommand" and re-run Pkg.build("PyCall").
Fetching package metadata ...............
Solving package specifications: .

# All requested packages already installed.
# packages in environment at /home/vagrant/.julia/v0.4/Conda/deps/usr:
#
numpy                     1.13.1          py27_blas_openblas_200  [blas_openblas]  conda-forge
INFO: PyCall is using /home/vagrant/.julia/v0.4/Conda/deps/usr/bin/python (Python 2.7.13) at /home/vagrant/.julia/v0.4/Conda/deps/usr/bin/python, libpython = /home/vagrant/.julia/v0.4/Conda/deps/usr/lib/libpython2.7
INFO: /home/vagrant/.julia/v0.4/PyCall/deps/deps.jl has not changed
INFO: /home/vagrant/.julia/v0.4/PyCall/deps/PYTHON has not changed
INFO: Package database updated
INFO: METADATA is out-of-date â€” you may not have the latest version of GeographicLibPy
INFO: Use `Pkg.update()` to get the latest versions of your packages

>>> 'Pkg.test("GeographicLibPy")' log
Julia Version 0.4.7
Commit ae26b25 (2016-09-18 16:17 UTC)
Platform Info:
  System: Linux (x86_64-pc-linux-gnu)
  CPU: Intel(R) Xeon(R) CPU E3-1241 v3 @ 3.50GHz
  WORD_SIZE: 64
           Ubuntu 14.04.5 LTS
  uname: Linux 3.13.0-121-generic #170-Ubuntu SMP Wed Jun 14 09:04:33 UTC 2017 x86_64 x86_64
Memory: 2.9392738342285156 GB (1181.1015625 MB free)
Uptime: 35341.0 sec
Load Avg:  1.02587890625  0.98486328125  0.9599609375
Intel(R) Xeon(R) CPU E3-1241 v3 @ 3.50GHz: 
       speed         user         nice          sys         idle          irq
#1  3500 MHz    1665440 s       3816 s     129179 s    1387829 s         57 s
#2  3500 MHz    1147241 s       2241 s     113680 s    2133860 s          0 s

  BLAS: libopenblas (USE64BITINT DYNAMIC_ARCH NO_AFFINITY Nehalem)
  LAPACK: libopenblas64_
  LIBM: libopenlibm
  LLVM: libLLVM-3.3
Environment:
  TERM = vt100
  LD_LIBRARY_PATH = :/usr/local/lib/
  PATH = /usr/local/sbin:/usr/local/bin:/usr/sbin:/usr/bin:/sbin:/bin:/usr/games:/usr/local/games:/home/vagrant/julia/bin/
  JAVA_HOME = /usr/lib/jvm/java-8-openjdk-amd64
  HOME = /home/vagrant

Package Directory: /home/vagrant/.julia/v0.4
2 required packages:
 - GeographicLibPy               0.0.3
 - JSON                          0.9.1
7 additional packages:
 - BinDeps                       0.4.7
 - Compat                        0.26.0
 - Conda                         0.5.3
 - MacroTools                    0.3.7
 - PyCall                        1.11.1
 - SHA                           0.3.3
 - URIParser                     0.1.8
INFO: Testing GeographicLibPy
ERROR: LoadError: InitError: PyError (:PyImport_ImportModule) <type 'exceptions.ImportError'>
ImportError('No module named geographiclib',)

 [inlined code] from /home/vagrant/.julia/v0.4/PyCall/src/exception.jl:81
 in pyimport at /home/vagrant/.julia/v0.4/PyCall/src/PyCall.jl:392
 in __init__ at /home/vagrant/.julia/v0.4/GeographicLibPy/src/GeographicLibPy.jl:16
 in _include_from_serialized at loading.jl:62
 in _require_from_serialized at loading.jl:87
 in require at ./loading.jl:280
 in include at ./boot.jl:261
 in include_from_node1 at ./loading.jl:333
 in process_options at ./client.jl:280
 in _start at ./client.jl:378
during initialization of module GeographicLibPy
while loading /home/vagrant/.julia/v0.4/GeographicLibPy/test/runtests.jl, in expression starting on line 3
===========================[ ERROR: GeographicLibPy ]===========================

failed process: Process(`/home/vagrant/julia/bin/julia --check-bounds=yes --code-coverage=none --color=no /home/vagrant/.julia/v0.4/GeographicLibPy/test/runtests.jl`, ProcessExited(1)) [1]

================================================================================
ERROR: GeographicLibPy had test errors
 in error at ./error.jl:21
 in test at pkg/entry.jl:803
 in anonymous at pkg/dir.jl:31
 in cd at file.jl:22
 in cd at pkg/dir.jl:31
 in test at pkg.jl:71
 in process_options at ./client.jl:257
 in _start at ./client.jl:378

>>> End of log
